Workbook

Sheet Billing - 8 Field Street
A1: ='Raw Billing'!O2 -> 8 Field Street Main Electrical | F1: 1.0173955 | S1: Factor (kVA) | T1: 1.0385
A2: ='Raw Billing'!A116 -> Range: From 2026-07-01 00:01 to 2026-08-01 00:00 | S2: Factor (kWh) | T2: 1.0174598
A3: ='Raw Billing'!O52 -> Ekurhuleni_Tariff_E_TOU_8 Field Street
A4: Entry | B4: Rate | C4: Unit | D4: Reading | E4: Cost | F4: Comment
A5: Fixed Charge | B5: ='Raw Billing'!B119 -> 5676.25 | C5: R/c | D5: ='Raw Billing'!D119 -> 1 | E5: =D5*B5 -> 5676.25
A6: Network Access | B6: ='Raw Billing'!B120 -> 112.25 | C6: R/kVA | D6: ='Raw Billing'!D120*$T$1 -> 628.48639 | E6: =D6*B6 -> 70547.597 | F6: ='Raw Billing'!F120 -> 46218.917
A7: Network Demand | B7: ='Raw Billing'!B121 -> 159.25 | C7: R/kVA | D7: ='Raw Billing'!D121*$T$1 -> 628.48639 | E7: =D7*B7 -> 100086.46 | F7: =F6 -> 46218.917
A8: Peak Energy - High Demand | B8: ='Raw Billing'!B122 -> 11.4354 | C8: R/kWh | D8: ='Raw Billing'!D122*$T$2 -> 54891.823 | E8: =D8*B8 -> 627709.95
A9: Peak Energy - Low Demand | B9: ='Raw Billing'!B123 -> 3.7227 | C9: R/kWh | D9: ='Raw Billing'!D123*$T$2 -> 0 | E9: =D9*B9 -> 0
A10: Standard Energy - High Demand | B10: ='Raw Billing'!B124 -> 3.3142 | C10: R/kWh | D10: ='Raw Billing'!D124*$T$2 -> 117534.54 | E10: =D10*B10 -> 389532.98
A11: Standard Energy - Low Demand | B11: ='Raw Billing'!B125 -> 2.4324 | C11: R/kWh | D11: ='Raw Billing'!D125*$T$2 -> 0 | E11: =D11*B11 -> 0
A12: Off-Peak Energy - High Demand | B12: ='Raw Billing'!B126 -> 2.0286 | C12: R/kWh | D12: ='Raw Billing'!D126*$T$2 -> 140252.84 | E12: =D12*B12 -> 284516.92
A13: Off-Peak Energy - Low Demand | B13: ='Raw Billing'!B127 -> 1.8451 | C13: R/kWh | D13: ='Raw Billing'!D127*$T$2 -> 0 | E13: =D13*B13 -> 0
A14: Total (Excl VAT) | E14: =SUM(E5:E13) -> 1478070.2
A17: Water & Sanitation | B17: Rate | C17: Unit | D17: Reading | E17: Cost
A18: Water Consumption | B18: ='Raw Billing'!B131 -> 54.51 | C18: R/kL | D18: ='Raw Billing'!D131 -> 197.61 | E18: =D18*B18 -> 10771.721
A19: Sewer | B19: ='Raw Billing'!B132 -> 22.07 | C19: R/kL | D19: =D18 -> 197.61 | E19: =D19*B19 -> 4361.2527
A20: Total (Ex VAT) | E20: =SUM(E18:E19) -> 15132.974
A22: Sub Total (Ex VAT) | E22: =E20+E14 -> 1493203.1

Sheet Raw Billing
A1: 45839 | O1: 45870
A2: 8 Field Street Main Electrical | O2: 8 Field Street Main Electrical
A3: Range: From 2025-07-01 00:01 to 2025-08-01 00:00 | O3: Range: From 2025-08-01 00:01 to 2025-09-01 00:00
A4: 8_Field_Street_Ekurhuleni_Tariff_E | O4: 8_Field_Street_Ekurhuleni_Tariff_E
A5: Entry | B5: Rate | C5: Unit | D5: Reading | E5: Cost | F5: Comment | O5: Entry | P5: Rate | Q5: Unit | R5: Reading | S5: Cost | T5: Comment
A6: Fixed Charge | B6: 5694.3279 | C6: R/c | D6: 1 | E6: 5694.3279 | O6: Fixed Charge | P6: 5694.3279 | Q6: R/c | R6: 1 | S6: 5694.3279
A7: Network Access | B7: 107.5628 | C7: R/kVA | D7: 587.57676 | E7: 63201.402 | F7: 45849.292 | O7: Network Access | P7: 107.5628 | Q7: R/kVA | R7: 590.28719 | S7: 63492.943 | T7: 45882.875
A8: Network Demand | B8: 161.8608 | C8: R/kVA | D8: 587.57676 | E8: 95105.645 | F8: 45849.292 | O8: Network Demand | P8: 161.8608 | Q8: R/kVA | R8: 590.28719 | S8: 95544.356 | T8: 45882.875
A9: Peak Energy - High Demand | B9: 11.4252 | C9: R/kWh | D9: 47510.48 | E9: 542816.74 | O9: Peak Energy - High Demand | P9: 11.4252 | Q9: R/kWh | R9: 38622.49 | S9: 441269.67
A10: Peak Energy - Low Demand | B10: 3.7132 | C10: R/kWh | D10: 0 | E10: 0 | O10: Peak Energy - Low Demand | P10: 3.7132 | Q10: R/kWh | R10: 0 | S10: 0
A11: Standard Energy - High Demand | B11: 3.3047 | C11: R/kWh | D11: 99886.55 | E11: 330095.08 | O11: Standard Energy - High Demand | P11: 3.3047 | Q11: R/kWh | R11: 84308.26 | S11: 278613.51
A12: Standard Energy - Low Demand | B12: 2.4231 | C12: R/kWh | D12: 0 | E12: 0 | O12: Standard Energy - Low Demand | P12: 2.4231 | Q12: R/kWh | R12: 0 | S12: 0
A13: Off-Peak Energy - High Demand | B13: 2.0192 | C13: R/kWh | D13: 115380.42 | E13: 232976.14 | O13: Off-Peak Energy - High Demand | P13: 2.0192 | Q13: R/kWh | R13: 122621.9 | S13: 247598.14
A14: Off-Peak Energy - Low Demand | B14: 1.8357 | C14: R/kWh | D14: 0 | E14: 0 | O14: Off-Peak Energy - Low Demand | P14: 1.8357 | Q14: R/kWh | R14: 0 | S14: 0
A15: Total | E15: 1269889.3 | O15: Total | S15: 1132212.9
A17: 45901 | O17: 45931
A18: 8 Field Street Main Electrical | O18: 8 Field Street Main Electrical
A19: Range: From 2025-09-01 00:01 to 2025-10-01 00:00 | O19: Range: From 2025-10-01 00:01 to 2025-11-01 00:00
A20: 8_Field_Street_Ekurhuleni_Tariff_E | O20: 8_Field_Street_Ekurhuleni_Tariff_E
A21: Entry | B21: Rate | C21: Unit | D21: Reading | E21: Cost | F21: Comment | O21: Entry | P21: Rate | Q21: Unit | R21: Reading | S21: Cost | T21: Comment
A22: Fixed Charge | B22: 5694.3279 | C22: R/c | D22: 1 | E22: 5694.3279 | O22: Fixed Charge | P22: 5694.3279 | Q22: R/c | R22: 1 | S22: 5694.3279
A23: Network Access | B23: 107.5628 | C23: R/kVA | D23: 600.92184 | E23: 64636.835 | F23: 45910.917 | O23: Network Access | P23: 107.5628 | Q23: R/kVA | R23: 592.43737 | S23: 63724.222 | T23: 45952.875
A24: Network Demand | B24: 161.8608 | C24: R/kVA | D24: 600.92184 | E24: 97265.689 | F24: 45910.917 | O24: Network Demand | P24: 161.8608 | Q24: R/kVA | R24: 592.43737 | S24: 95892.386 | T24: 45952.875
A25: Peak Energy - High Demand | B25: 11.4252 | C25: R/kWh | D25: 0 | E25: 0 | O25: Peak Energy - High Demand | P25: 11.4252 | Q25: R/kWh | R25: 0 | S25: 0
A26: Peak Energy - Low Demand | B26: 3.7132 | C26: R/kWh | D26: 46140.52 | E26: 171328.98 | O26: Peak Energy - Low Demand | P26: 3.7132 | Q26: R/kWh | R26: 49665.88 | S26: 184419.35
A27: Standard Energy - High Demand | B27: 3.3047 | C27: R/kWh | D27: 0 | E27: 0 | O27: Standard Energy - High Demand | P27: 3.3047 | Q27: R/kWh | R27: 0 | S27: 0
A28: Standard Energy - Low Demand | B28: 2.4231 | C28: R/kWh | D28: 107174.03 | E28: 259693.39 | O28: Standard Energy - Low Demand | P28: 2.4231 | Q28: R/kWh | R28: 107005.79 | S28: 259285.73
A29: Off-Peak Energy - High Demand | B29: 2.0192 | C29: R/kWh | D29: 0 | E29: 0 | O29: Off-Peak Energy - High Demand | P29: 2.0192 | Q29: R/kWh | R29: 0 | S29: 0
A30: Off-Peak Energy - Low Demand | B30: 1.8357 | C30: R/kWh | D30: 147138.53 | E30: 270102.2 | O30: Off-Peak Energy - Low Demand | P30: 1.8357 | Q30: R/kWh | R30: 138035.11 | S30: 253391.05
A31: Total | E31: 868721.42 | O31: Total | S31: 862407.06
A33: 45962 | O33: 45992
A34: 8 Field Street Main Electrical | O34: 8 Field Street Main Electrical
A35: Range: From 2025-11-01 00:01 to 2025-12-01 00:00 | O35: Range: From 2025-12-01 00:01 to 2026-01-01 00:00
A36: 8_Field_Street_Ekurhuleni_Tariff_E | O36: 8_Field_Street_Ekurhuleni_Tariff_E
A37: Entry | B37: Rate | C37: Unit | D37: Reading | E37: Cost | F37: Comment | O37: Entry | P37: Rate | Q37: Unit | R37: Reading | S37: Cost | T37: Comment
A38: Fixed Charge | B38: 5694.3279 | C38: R/c | D38: 1 | E38: 5694.3279 | O38: Fixed Charge | P38: 5694.3279 | Q38: R/c | R38: 1 | S38: 5694.3279
A39: Network Access | B39: 107.5628 | C39: R/kVA | D39: 587.63589 | E39: 63207.762 | F39: 45988.854 | O39: Network Access | P39: 107.5628 | Q39: R/kVA | R39: 576.4634 | S39: 62006.017 | T39: 45995.833
A40: Network Demand | B40: 161.8608 | C40: R/kVA | D40: 587.63589 | E40: 95115.215 | F40: 45988.854 | O40: Network Demand | P40: 161.8608 | Q40: R/kVA | R40: 576.4634 | S40: 93306.827 | T40: 45995.833
A41: Peak Energy - High Demand | B41: 11.4252 | C41: R/kWh | D41: 0 | E41: 0 | O41: Peak Energy - High Demand | P41: 11.4252 | Q41: R/kWh | R41: 0 | S41: 0
A42: Peak Energy - Low Demand | B42: 3.7132 | C42: R/kWh | D42: 40347.68 | E42: 149819.01 | O42: Peak Energy - Low Demand | P42: 3.7132 | Q42: R/kWh | R42: 30983.01 | S42: 115046.11
...

Sheet Tariffs
B1: Electricity Tariff
E2: 2025/2026 | G2: 2026/2027
B3: E.1.2 | C3: Basic Charge | D3: R/Month | E3: 5694.3279 | F3: 5207.09 | G3: 5676.25
B4: E.2.1.3. | C4: Demand Charge | D4: R/kVA | E4: 161.8608 | F4: 146.09 | G4: 159.25
B5: E.2.3.3. | C5: NAC | D5: R/kVA | E5: 107.5628 | F5: 105.9466 | G5: 105.33
B6: E.3.1.3. | C6: High Demand - Peak | D6: R/kWh | E6: 10.678 | F6: 10.486 | G6: 11.4354
B7: E.3.1.6. | C7: High Demand - STD | D7: R/kWh | E7: 3.0801 | F7: 3.036 | G7: 3.3142
B8: E.3.1.9. | C8: High Demand - Off-Peak | D8: R/kWh | E8: 1.8822 | F8: 1.848 | G8: 2.0286
B9: E.3.2.3. | C9: Low Demand - Peak | D9: R/kWh | E9: 3.4765 | F9: 3.415 | G9: 3.7227
B10: E.3.2.6. | C10: Low Demand - Std | D10: R/kWh | E10: 2.263 | F10: 2.231 | G10: 2.4324
B11: E.3.2.9. | C11: Low Demand - Off-Peak | D11: R/kWh | E11: 1.7125 | F11: 1.693 | G11: 1.8451
B13: Water Tariff
C14: 2025/2026 | D14: 2026/2027
B15: 0 - 5 000 kl/month | C15: 49.11 | D15: 54.51
B16: 5 001 - 25 000 kl/month | C16: 49.88 | D16: 55.37
B17: 25 001 - | C17: 52.05 | D17: 57.78
B19: Sewerage Tariff
C20: 2025/2026 | D20: 2026/2027
B21: 0 - 3 500 kl/month | C21: 18.91 | D21: 22.07
B22: 3501 - 7000 kL/month | C22: 0 | D22: 20.49
B23: 7001 - 15000 kL/month | C23: 10.09 | D23: 11.77
B24: 15001 - 25000 kL/month | C24: 0 | D24: 10.93
B25: 25001 - kL/month | C25: 6.56 | D25: 7.66
B26: =B25 -> 25001 - kL/month | C26: 6.56 | D26: 7.11

Sheet Comparison
A1: 8 Field Street COE - Bill | B1: COE - Electricity
B2: Munic Monthly Bill | C2: Peak (Low) | D2: Peak Charge (Low) | E2: Peak (High) | F2: Peak Charge (High) | G2: Peak Total | H2: Off-Peak (Low) | I2: Off-Peak Charge (Low) | J2: Off-Peak (High) | K2: Off-Peak Charge (High) | L2: Off-Peak total | M2: Standard (Low) | N2: Standard Charge (Low) | O2: Standard (High) | P2: Standard Charge (High) | Q2: Standard Total | R2: Demand | S2: Demand Charge | T2: Demand Charge Total | U2: Network Access Charge | V2: Network Access Total | W2: Basic Charge | X2: Total Bill | Z2: Total Consumption Charges | AA2: Total | AB2: Total
B3: (Fill in table from bills) | C3: (kWh) | D3: (R/kWh) | E3: (kWh) | F3: (R/kWh) | G3: (R) | H3: (kWh) | I3: (R/kWh) | J3: (kWh) | K3: (R/kWh) | L3: (R) | M3: (kWh) | N3: (R/kWh) | O3: (kWh) | P3: (R/kWh) | Q3: (R) | R3: (kVA) | S3: (R) | T3: (R) | U3: (R) | V3: (R) | W3: (R) | X3: (R) | Z3: (R) | AA3: R/kWh | AB3: R/kVA
B4: 45839 | G4: =C4*D4+E4*F4 -> 0 | L4: =H4*I4+J4*K4 -> 0 | Q4: =M4*N4+O4*P4 -> 0 | T4: =S4*R4 -> 0 | V4: =U4*R4 -> 0 | X4: =G4+L4+Q4+T4+V4+W4 -> 0 | Z4: =G4+L4+Q4 -> 0 | AA4: =IFERROR(Z4/(SUM(C4,E4,H4,J4,M4,O4)),0) -> 0 | AB4: =IFERROR((T4+V4)/R4,0) -> 0
B5: 45870 | G5: =C5*D5+E5*F5 -> 0 | L5: =H5*I5+J5*K5 -> 0 | Q5: =M5*N5+O5*P5 -> 0 | T5: =S5*R5 -> 0 | V5: =U5*R5 -> 0 | X5: =G5+L5+Q5+T5+V5+W5 -> 0 | Z5: =G5+L5+Q5 -> 0 | AA5: =IFERROR(Z5/(SUM(C5,E5,H5,J5,M5,O5)),0) -> 0 | AB5: =IFERROR((T5+V5)/R5,0) -> 0
B6: 45901 | G6: =C6*D6+E6*F6 -> 0 | L6: =H6*I6+J6*K6 -> 0 | Q6: =M6*N6+O6*P6 -> 0 | T6: =S6*R6 -> 0 | V6: =U6*R6 -> 0 | X6: =G6+L6+Q6+T6+V6+W6 -> 0 | Z6: =G6+L6+Q6 -> 0 | AA6: =IFERROR(Z6/(SUM(C6,E6,H6,J6,M6,O6)),0) -> 0 | AB6: =IFERROR((T6+V6)/R6,0) -> 0
B7: 45931 | G7: =C7*D7+E7*F7 -> 0 | L7: =H7*I7+J7*K7 -> 0 | Q7: =M7*N7+O7*P7 -> 0 | T7: =S7*R7 -> 0 | V7: =U7*R7 -> 0 | X7: =G7+L7+Q7+T7+V7+W7 -> 0 | Z7: =G7+L7+Q7 -> 0 | AA7: =IFERROR(Z7/(SUM(C7,E7,H7,J7,M7,O7)),0) -> 0 | AB7: =IFERROR((T7+V7)/R7,0) -> 0
B8: 45962 | G8: =C8*D8+E8*F8 -> 0 | L8: =H8*I8+J8*K8 -> 0 | Q8: =M8*N8+O8*P8 -> 0 | T8: =S8*R8 -> 0 | V8: =U8*R8 -> 0 | X8: =G8+L8+Q8+T8+V8+W8 -> 0 | Z8: =G8+L8+Q8 -> 0 | AA8: =IFERROR(Z8/(SUM(C8,E8,H8,J8,M8,O8)),0) -> 0 | AB8: =IFERROR((T8+V8)/R8,0) -> 0
B9: 45992 | G9: =C9*D9+E9*F9 -> 0 | L9: =H9*I9+J9*K9 -> 0 | Q9: =M9*N9+O9*P9 -> 0 | T9: =S9*R9 -> 0 | V9: =U9*R9 -> 0 | X9: =G9+L9+Q9+T9+V9+W9 -> 0 | Z9: =G9+L9+Q9 -> 0 | AA9: =IFERROR(Z9/(SUM(C9,E9,H9,J9,M9,O9)),0) -> 0 | AB9: =IFERROR((T9+V9)/R9,0) -> 0
B10: 46023 | G10: =C10*D10+E10*F10 -> 0 | L10: =H10*I10+J10*K10 -> 0 | Q10: =M10*N10+O10*P10 -> 0 | T10: =S10*R10 -> 0 | V10: =U10*R10 -> 0 | X10: =G10+L10+Q10+T10+V10+W10 -> 0 | Z10: =G10+L10+Q10 -> 0 | AA10: =IFERROR(Z10/(SUM(C10,E10,H10,J10,M10,O10)),0) -> 0 | AB10: =IFERROR((T10+V10)/R10,0) -> 0
B11: 46054 | G11: =C11*D11+E11*F11 -> 0 | L11: =H11*I11+J11*K11 -> 0 | Q11: =M11*N11+O11*P11 -> 0 | T11: =S11*R11 -> 0 | V11: =U11*R11 -> 0 | X11: =G11+L11+Q11+T11+V11+W11 -> 0 | Z11: =G11+L11+Q11 -> 0 | AA11: =IFERROR(Z11/(SUM(C11,E11,H11,J11,M11,O11)),0) -> 0 | AB11: =IFERROR((T11+V11)/R11,0) -> 0
B12: 46082 | G12: =C12*D12+E12*F12 -> 0 | L12: =H12*I12+J12*K12 -> 0 | Q12: =M12*N12+O12*P12 -> 0 | T12: =S12*R12 -> 0 | V12: =U12*R12 -> 0 | X12: =G12+L12+Q12+T12+V12+W12 -> 0 | Z12: =G12+L12+Q12 -> 0 | AA12: =IFERROR(Z12/(SUM(C12,E12,H12,J12,M12,O12)),0) -> 0 | AB12: =IFERROR((T12+V12)/R12,0) -> 0
B13: 46113 | G13: =C13*D13+E13*F13 -> 0 | L13: =H13*I13+J13*K13 -> 0 | Q13: =M13*N13+O13*P13 -> 0 | T13: =S13*R13 -> 0 | V13: =U13*R13 -> 0 | X13: =G13+L13+Q13+T13+V13+W13 -> 0 | Z13: =G13+L13+Q13 -> 0 | AA13: =IFERROR(Z13/(SUM(C13,E13,H13,J13,M13,O13)),0) -> 0 | AB13: =IFERROR((T13+V13)/R13,0) -> 0
B14: 46143 | G14: =C14*D14+E14*F14 -> 0 | L14: =H14*I14+J14*K14 -> 0 | Q14: =M14*N14+O14*P14 -> 0 | T14: =S14*R14 -> 0 | V14: =U14*R14 -> 0 | X14: =G14+L14+Q14+T14+V14+W14 -> 0 | Z14: =G14+L14+Q14 -> 0 | AA14: =IFERROR(Z14/(SUM(C14,E14,H14,J14,M14,O14)),0) -> 0 | AB14: =IFERROR((T14+V14)/R14,0) -> 0
B15: 46174 | G15: =C15*D15+E15*F15 -> 0 | L15: =H15*I15+J15*K15 -> 0 | Q15: =M15*N15+O15*P15 -> 0 | T15: =S15*R15 -> 0 | V15: =U15*R15 -> 0 | X15: =G15+L15+Q15+T15+V15+W15 -> 0 | Z15: =G15+L15+Q15 -> 0 | AA15: =IFERROR(Z15/(SUM(C15,E15,H15,J15,M15,O15)),0) -> 0 | AB15: =IFERROR((T15+V15)/R15,0) -> 0
... B21: 46357 | G21: =C21*D21+E21*F21 -> 0 | L21: =H21*I21+J21*K21 -> 0 | Q21: =M21*N21+O21*P21 -> 0 | T21: =S21*R21 -> 0 | V21: =U21*R21 -> 0 | X21: =G21+L21+Q21+T21+V21+W21 -> 0 | Z21: =G21+L21+Q21 -> 0 | AA21: =IFERROR(Z21/(SUM(C21,E21,H21,J21,M21,O21)),0) -> 0 | AB21: =IFERROR((T21+V21)/R21,0) -> 0
B22: AVERAGE PER MONTH | C22: =AVERAGE(C4:C21) -> #DIV/0! | D22: =AVERAGE(D4:D21) -> #DIV/0! | E22: =AVERAGE(E4:E21) -> #DIV/0! | F22: =AVERAGE(F4:F21) -> #DIV/0! | G22: =AVERAGE(G4:G21) -> 0 | H22: =AVERAGE(H4:H21) -> #DIV/0! | I22: =AVERAGE(I4:I21) -> #DIV/0! | J22: =AVERAGE(J4:J21) -> #DIV/0! | ... AB22: =AVERAGE(AB4:AB21) -> 0
A24: 8 Field Street HS - Bill | B24: HolmStone - Electricity
B25: Munic Monthly Bill | C25: Peak (Low) | D25: Peak Charge (Low) | E25: Peak (High) | F25: Peak Charge (High) | G25: Peak Total | H25: Off-Peak (Low) | I25: Off-Peak Charge (Low) | J25: Off-Peak (High) | K25: Off-Peak Charge (High) | L25: Off-Peak total | M25: Standard (Low) | N25: Standard Charge (Low) | O25: Standard (High) | P25: Standard Charge (High) | Q25: Standard Total | R25: Demand | S25: Demand Charge | T25: Demand Charge Total | U25: Network Access Charge | V25: Network Access Total | W25: Basic Charge | X25: Total Bill | Z25: Total Consumption Charges | AA25: Total | AB25: Total
B26: (Fill in table from bills) | C26: (kWh) | D26: (R/kWh) | E26: (kWh) | F26: (R/kWh) | G26: (R) | H26: (kWh) | I26: (R/kWh) | J26: (kWh) | K26: (R/kWh) | L26: (R) | M26: (kWh) | N26: (R/kWh) | O26: (kWh) | P26: (R/kWh) | Q26: (R) | R26: (kVA) | S26: (R) | T26: (R) | U26: (R) | V26: (R) | W26: (R) | X26: (R) | Z26: (R) | AA26: R/kWh | AB26: R/kVA
B27: 45839 | E27: ='Raw Billing'!D9 -> 47510.48 | F27: ='Raw Billing'!B9 -> 11.4252 | G27: =C27*D27+E27*F27 -> 542816.74 | J27: ='Raw Billing'!D13 -> 115380.42 | K27: ='Raw Billing'!B13 -> 2.0192 | L27: =H27*I27+J27*K27 -> 232976.14 | O27: ='Raw Billing'!D11 -> 99886.55 | P27: ='Raw Billing'!B11 -> 3.3047 | Q27: =M27*N27+O27*P27 -> 330095.08 | R27: ='Raw Billing'!D7 -> 587.57676 | S27: ='Raw Billing'!B8 -> 161.8608 | T27: =S27*R27 -> 95105.645 | U27: ='Raw Billing'!B7 -> 107.5628 | V27: =U27*R27 -> 63201.402 | W27: ='Raw Billing'!B6 -> 5694.3279 | X27: =G27+L27+Q27+T27+V27+W27 -> 1269889.3 | Z27: =G27+L27+Q27 -> 1105888 | AA27: =IFERROR(Z27/(SUM(C27,E27,H27,J27,M27,O27)),0) -> 4.2084584 | AB27: =IFERROR((T27+V27)/R27,0) -> 269.4236
B28: 45870 | E28: ='Raw Billing'!R9 -> 38622.49 | F28: =F27 -> 11.4252 | G28: =C28*D28+E28*F28 -> 441269.67 | J28: ='Raw Billing'!R13 -> 122621.9 | K28: =K27 -> 2.0192 | L28: =H28*I28+J28*K28 -> 247598.14 | O28: ='Raw Billing'!R11 -> 84308.26 | P28: =P27 -> 3.3047 | Q28: =M28*N28+O28*P28 -> 278613.51 | R28: ='Raw Billing'!R7 -> 590.28719 | S28: =S27 -> 161.8608 | T28: =S28*R28 -> 95544.356 | U28: =U27 -> 107.5628 | V28: =U28*R28 -> 63492.943 | W28: =W27 -> 5694.3279 | X28: =G28+L28+Q28+T28+V28+W28 -> 1132212.9 | Z28: =G28+L28+Q28 -> 967481.32 | AA28: =IFERROR(Z28/(SUM(C28,E28,H28,J28,M28,O28)),0) -> 3.9400158 | AB28: =IFERROR((T28+V28)/R28,0) -> 269.4236
B29: 45901 | C29: ='Raw Billing'!D26 -> 46140.52 | D29: ='Raw Billing'!B26 -> 3.7132 | G29: =C29*D29+E29*F29 -> 171328.98 | H29: ='Raw Billing'!D30 -> 147138.53 | I29: ='Raw Billing'!B30 -> 1.8357 | L29: =H29*I29+J29*K29 -> 270102.2 | M29: ='Raw Billing'!D28 -> 107174.03 | N29: ='Raw Billing'!B28 -> 2.4231 | Q29: =M29*N29+O29*P29 -> 259693.39 | R29: ='Raw Billing'!D23 -> 600.92184 | S29: =S28 -> 161.8608 | T29: =S29*R29 -> 97265.689 | U29: =U28 -> 107.5628 | V29: =U29*R29 -> 64636.835 | W29: =W28 -> 5694.3279 | X29: =G29+L29+Q29+T29+V29+W29 -> 868721.42 | Z29: =G29+L29+Q29 -> 701124.57 | AA29: =IFERROR(Z29/(SUM(C29,E29,H29,J29,M29,O29)),0) -> 2.3335576 | AB29: =IFERROR((T29+V29)/R29,0) -> 269.4236
B30: 45931 | C30: ='Raw Billing'!R26 -> 49665.88 | D30: =D29 -> 3.7132 | G30: =C30*D30+E30*F30 -> 184419.35 | H30: ='Raw Billing'!R30 -> 138035.11 | I30: =I29 -> 1.8357 | L30: =H30*I30+J30*K30 -> 253391.05 | M30: ='Raw Billing'!R28 -> 107005.79 | N30: =N29 -> 2.4231 | Q30: =M30*N30+O30*P30 -> 259285.73 | R30: ='Raw Billing'!R23 -> 592.43737 | S30: =S29 -> 161.8608 | T30: =S30*R30 -> 95892.386 | U30: =U29 -> 107.5628 | V30: =U30*R30 -> 63724.222 | W30: =W29 -> 5694.3279 | X30: =G30+L30+Q30+T30+V30+W30 -> 862407.06 | Z30: =G30+L30+Q30 -> 697096.13 | AA30: =IFERROR(Z30/(SUM(C30,E30,H30,J30,M30,O30)),0) -> 2.3653888 | AB30: =IFERROR((T30+V30)/R30,0) -> 269.4236
B31: 45962 | C31: ='Raw Billing'!D42 -> 40347.68 | D31: =D30 -> 3.7132 | G31: =C31*D31+E31*F31 -> 149819.01 | H31: ='Raw Billing'!D46 -> 125695.44 | I31: =I30 -> 1.8357 | L31: =H31*I31+J31*K31 -> 230739.12 | M31: ='Raw Billing'!D44 -> 93869.99 | N31: =N30 -> 2.4231 | Q31: =M31*N31+O31*P31 -> 227456.37 | R31: ='Raw Billing'!D39 -> 587.63589 | S31: =S30 -> 161.8608 | T31: =S31*R31 -> 95115.215 | U31: =U30 -> 107.5628 | V31: =U31*R31 -> 63207.762 | W31: =W30 -> 5694.3279 | X31: =G31+L31+Q31+T31+V31+W31 -> 772031.8 | Z31: =G31+L31+Q31 -> 608014.5 | AA31: =IFERROR(Z31/(SUM(C31,E31,H31,J31,M31,O31)),0) -> 2.3392991 | AB31: =IFERROR((T31+V31)/R31,0) -> 269.4236
B32: 45992 | C32: ='Raw Billing'!R42 -> 30983.01 | D32: =D31 -> 3.7132 | G32: =C32*D32+E32*F32 -> 115046.11 | H32: ='Raw Billing'!R46 -> 108748.62 | I32: =I31 -> 1.8357 | L32: =H32*I32+J32*K32 -> 199629.84 | M32: ='Raw Billing'!R44 -> 76012.39 | N32: =N31 -> 2.4231 | Q32: =M32*N32+O32*P32 -> 184185.62 | R32: ='Raw Billing'!R39 -> 576.4634 | S32: =S31 -> 161.8608 | T32: =S32*R32 -> 93306.827 | U32: =U31 -> 107.5628 | V32: =U32*R32 -> 62006.017 | W32: =W31 -> 5694.3279 | X32: =G32+L32+Q32+T32+V32+W32 -> 659868.75 | Z32: =G32+L32+Q32 -> 498861.58 | AA32: =IFERROR(Z32/(SUM(C32,E32,H32,J32,M32,O32)),0) -> 2.3122846 | AB32: =IFERROR((T32+V32)/R32,0) -> 269.4236
B33: 46023 | C33: ='Raw Billing'!D58 -> 40917.38 | D33: =D32 -> 3.7132 | G33: =C33*D33+E33*F33 -> 151934.42 | H33: ='Raw Billing'!D62 -> 113724.34 | I33: =I32 -> 1.8357 | L33: =H33*I33+J33*K33 -> 208763.77 | M33: ='Raw Billing'!D60 -> 88116.32 | N33: =N32 -> 2.4231 | Q33: =M33*N33+O33*P33 -> 213514.65 | R33: ='Raw Billing'!D55 -> 595.78727 | S33: =S32 -> 161.8608 | T33: =S33*R33 -> 96434.604 | U33: =U32 -> 107.5628 | V33: =U33*R33 -> 64084.547 | W33: =W32 -> 5694.3279 | X33: =G33+L33+Q33+T33+V33+W33 -> 740426.32 | Z33: =G33+L33+Q33 -> 574212.84 | AA33: =IFERROR(Z33/(SUM(C33,E33,H33,J33,M33,O33)),0) -> 2.3653711 | AB33: =IFERROR((T33+V33)/R33,0) -> 269.4236
B34: 46054 | C34: ='Raw Billing'!R58 -> 37054.89 | D34: =D33 -> 3.7132 | G34: =C34*D34+E34*F34 -> 137592.22 | H34: ='Raw Billing'!Y62 -> 104607.6 | I34: =I33 -> 1.8357 | L34: =H34*I34+J34*K34 -> 192028.17 | M34: ='Raw Billing'!Y60 -> 80308.8 | N34: =N33 -> 2.4231 | Q34: =M34*N34+O34*P34 -> 194596.25 | R34: ='Raw Billing'!Y55 -> 592.819 | S34: ='Raw Billing'!P56 -> 146.09 | T34: =S34*R34 -> 86604.928 | U34: ='Raw Billing'!P55 -> 105.9466 | V34: =U34*R34 -> 62807.157 | W34: ='Raw Billing'!P79 -> 5207.09 | X34: =G34+L34+Q34+T34+V34+W34 -> 678835.82 | Z34: =G34+L34+Q34 -> 524216.64 | AA34: =IFERROR(Z34/(SUM(C34,E34,H34,J34,M34,O34)),0) -> 2.3616416 | AB34: =IFERROR((T34+V34)/R34,0) -> 252.0366
B35: 46082 | C35: ='Raw Billing'!K83 -> 43357.2 | D35: =D34 -> 3.7132 | G35: =C35*D35+E35*F35 -> 160993.96 | H35: ='Raw Billing'!K85 -> 94513.199 | I35: =I34 -> 1.8357 | L35: =H35*I35+J35*K35 -> 173497.88 | M35: ='Raw Billing'!K85 -> 94513.199 | N35: =N34 -> 2.4231 | Q35: =M35*N35+O35*P35 -> 229014.93 | R35: ='Raw Billing'!K80 -> 630.688 | S35: =S34 -> 146.09 | T35: =S35*R35 -> 92137.21 | U35: =U34 -> 105.9466 | V35: =U35*R35 -> 66819.249 | W35: =W34 -> 5207.09 | X35: =G35+L35+Q35+T35+V35+W35 -> 727670.32 | Z35: =G35+L35+Q35 -> 563506.77 | AA35: =IFERROR(Z35/(SUM(C35,E35,H35,J35,M35,O35)),0) -> 2.4248991 | AB35: =IFERROR((T35+V35)/R35,0) -> 252.0366
B36: 46113 | C36: ='Raw Billing'!R83 -> 41631.11 | D36: =D35 -> 3.7132 | G36: =C36*D36+E36*F36 -> 154584.64 | H36: ='Raw Billing'!R87 -> 139319.34 | I36: =I35 -> 1.8357 | L36: =H36*I36+J36*K36 -> 255748.51 | M36: ='Raw Billing'!R85 -> 95711.72 | N36: =N35 -> 2.4231 | Q36: =M36*N36+O36*P36 -> 231919.07 | R36: ='Raw Billing'!R80 -> 596.81709 | S36: =S35 -> 146.09 | T36: =S36*R36 -> 87189.008 | U36: =U35 -> 105.9466 | V36: =U36*R36 -> 63230.741 | W36: =W35 -> 5207.09 | X36: =G36+L36+Q36+T36+V36+W36 -> 797879.06 | Z36: =G36+L36+Q36 -> 642252.22 | AA36: =IFERROR(Z36/(SUM(C36,E36,H36,J36,M36,O36)),0) -> 2.3214313 | AB36: =IFERROR((T36+V36)/R36,0) -> 252.0366
B37: 46143 | C37: ='Raw Billing'!D107 -> 45649.32 | D37: =D36 -> 3.7132 | G37: =C37*D37+E37*F37 -> 169505.06 | H37: ='Raw Billing'!D111 -> 139985.44 | I37: =I36 -> 1.8357 | L37: =H37*I37+J37*K37 -> 256971.27 | M37: ='Raw Billing'!D109 -> 103848.27 | N37: =N36 -> 2.4231 | Q37: =M37*N37+O37*P37 -> 251634.74 | R37: ='Raw Billing'!D104 -> 594.15233 | S37: =S36 -> 146.09 | T37: =S37*R37 -> 86799.714 | U37: =U36 -> 105.9466 | V37: =U37*R37 -> 62948.419 | W37: =W36 -> 5207.09 | X37: =G37+L37+Q37+T37+V37+W37 -> 833066.29 | Z37: =G37+L37+Q37 -> 678111.07 | AA37: =IFERROR(Z37/(SUM(C37,E37,H37,J37,M37,O37)),0) -> 2.3424899 | AB37: =IFERROR((T37+V37)/R37,0) -> 252.0366
B38: 46174 | E38: 41880 | F38: ='Raw Billing'!I106 -> 10.486 | G38: =C38*D38+E38*F38 -> 439153.68 | J38: 116686.8 | K38: ='Raw Billing'!I110 -> 1.848 | L38: =H38*I38+J38*K38 -> 215637.21 | O38: 95230.8 | P38: ='Raw Billing'!I108 -> 3.036 | Q38: =M38*N38+O38*P38 -> 289120.71 | R38: 602.634 | S38: =S37 -> 146.09 | T38: =S38*R38 -> 88038.801 | U38: 101.12 | V38: =U38*R38 -> 60938.35 | W38: 6195.35 | X38: =G38+L38+Q38+T38+V38+W38 -> 1099084.1 | Z38: =G38+L38+Q38 -> 943911.6 | AA38: =IFERROR(Z38/(SUM(C38,E38,H38,J38,M38,O38)),0) -> 3.719151 | AB38: =IFERROR((T38+V38)/R38,0) -> 247.21
B39: 46204 | E39: ='Billing - 8 Field Street'!D8 -> 54891.823 | F39: ='Raw Billing'!B122 -> 11.4354 | G39: =C39*D39+E39*F39 -> 627709.95 | J39: ='Billing - 8 Field Street'!D12 -> 140252.84 | K39: ='Raw Billing'!B126 -> 2.0286 | L39: =H39*I39+J39*K39 -> 284516.92 | O39: ='Billing - 8 Field Street'!D10 -> 117534.54 | P39: ='Raw Billing'!B124 -> 3.3142 | Q39: =M39*N39+O39*P39 -> 389532.98 | R39: ='Billing - 8 Field Street'!D6 -> 628.48639 | S39: ='Raw Billing'!B121 -> 159.25 | T39: =S39*R39 -> 100086.46 | U39: ='Raw Billing'!B120 -> 112.25 | V39: =U39*R39 -> 70547.597 | W39: ='Raw Billing'!B119 -> 5676.25 | X39: =G39+L39+Q39+T39+V39+W39 -> 1478070.2 | Z39: =G39+L39+Q39 -> 1301759.9 | AA39: =IFERROR(Z39/(SUM(C39,E39,H39,J39,M39,O39)),0) -> 4.163244 | AB39: =IFERROR((T39+V39)/R39,0) -> 271.5
B40: 46235 | G40: =C40*D40+E40*F40 -> 0 | L40: =H40*I40+J40*K40 -> 0 | Q40: =M40*N40+O40*P40 -> 0 | T40: =S40*R40 -> 0 | V40: =U40*R40 -> 0 | X40: =G40+L40+Q40+T40+V40+W40 -> 0 | Z40: =G40+L40+Q40 -> 0 | AA40: =IFERROR(Z40/(SUM(C40,E40,H40,J40,M40,O40)),0) -> 0 | AB40: =IFERROR((T40+V40)/R40,0) -> 0
B41: 46266 | G41: =C41*D41+E41*F41 -> 0 | L41: =H41*I41+J41*K41 -> 0 | Q41: =M41*N41+O41*P41 -> 0 | T41: =S41*R41 -> 0 | V41: =U41*R41 -> 0 | X41: =G41+L41+Q41+T41+V41+W41 -> 0 | Z41: =G41+L41+Q41 -> 0 | AA41: =IFERROR(Z41/(SUM(C41,E41,H41,J41,M41,O41)),0) -> 0 | AB41: =IFERROR((T41+V41)/R41,0) -> 0
B42: 46296 | G42: =C42*D42+E42*F42 -> 0 | L42: =H42*I42+J42*K42 -> 0 | Q42: =M42*N42+O42*P42 -> 0 | T42: =S42*R42 -> 0 | V42: =U42*R42 -> 0 | X42: =G42+L42+Q42+T42+V42+W42 -> 0 | Z42: =G42+L42+Q42 -> 0 | AA42: =IFERROR(Z42/(SUM(C42,E42,H42,J42,M42,O42)),0) -> 0 | AB42: =IFERROR((T42+V42)/R42,0) -> 0
B43: 46327 | G43: =C43*D43+E43*F43 -> 0 | L43: =H43*I43+J43*K43 -> 0 | Q43: =M43*N43+O43*P43 -> 0 | T43: =S43*R43 -> 0 | V43: =U43*R43 -> 0 | X43: =G43+L43+Q43+T43+V43+W43 -> 0 | Z43: =G43+L43+Q43 -> 0 | AA43: =IFERROR(Z43/(SUM(C43,E43,H43,J43,M43,O43)),0) -> 0 | AB43: =IFERROR((T43+V43)/R43,0) -> 0
B44: 46357 | G44: =C44*D44+E44*F44 -> 0 | L44: =H44*I44+J44*K44 -> 0 | Q44: =M44*N44+O44*P44 -> 0 | T44: =S44*R44 -> 0 | V44: =U44*R44 -> 0 | X44: =G44+L44+Q44+T44+V44+W44 -> 0 | Z44: =G44+L44+Q44 -> 0 | AA44: =IFERROR(Z44/(SUM(C44,E44,H44,J44,M44,O44)),0) -> 0 | AB44: =IFERROR((T44+V44)/R44,0) -> 0
B45: AVERAGE PER MONTH | C45: =AVERAGE(C27:C44) -> 41749.666 | D45: =AVERAGE(D27:D44) -> 3.7132 | E45: =AVERAGE(E27:E44) -> 45726.198 | F45: =AVERAGE(F27:F44) -> 11.19295 | G45: =AVERAGE(G27:G44) -> 191454.1 | H45: =AVERAGE(H27:H44) -> 123529.74 | I45: =AVERAGE(I27:I44) -> 1.8357 | J45: =AVERAGE(J27:J44) -> 123735.49 | ... AB45: =AVERAGE(AB27:AB44) -> 189.6012
A47: 8 Field Street HS - Bill | B47: 8 Field - HS Water
...
